Workbook

Sheet dump
A1: =chksum!A1 -> C000 | B1: =TEXT(chksum!B1,"00") -> FF | C1: =TEXT(chksum!C1,"00") -> FF | D1: =TEXT(chksum!D1,"00") -> FF | E1: =TEXT(chksum!E1,"00") -> FF | F1: =TEXT(chksum!F1,"00") -> FF | G1: =TEXT(chksum!G1,"00") -> FF | H1: =TEXT(chksum!H1,"00") -> FF | I1: =TEXT(chksum!I1,"00") -> FF | ... R1: =TEXT(chksum!R1,"00") -> F0 | T1: =_xlfn.TEXTJOIN(" ", TRUE, A1:R1) -> C000 FF FF FF FF FF FF FF FF FF FF FF FF FF FF FF FF F0
A2: =chksum!A2 -> C010 | B2: =TEXT(chksum!B2,"00") -> FF | C2: =TEXT(chksum!C2,"00") -> FF | D2: =TEXT(chksum!D2,"00") -> FF | E2: =TEXT(chksum!E2,"00") -> FF | F2: =TEXT(chksum!F2,"00") -> FF | G2: =TEXT(chksum!G2,"00") -> FF | H2: =TEXT(chksum!H2,"00") -> FF | I2: =TEXT(chksum!I2,"00") -> FF | ... R2: =TEXT(chksum!R2,"00") -> F5 | T2: =_xlfn.TEXTJOIN(" ", TRUE, A2:R2) -> C010 FF FF FF FF FF FF FF FF FF 80 80 FF 00 00 FF 00 F5
A3: =chksum!A3 -> C020 | B3: =TEXT(chksum!B3,"00") -> 00 | C3: =TEXT(chksum!C3,"00") -> FF | D3: =TEXT(chksum!D3,"00") -> 00 | E3: =TEXT(chksum!E3,"00") -> 00 | F3: =TEXT(chksum!F3,"00") -> FF | G3: =TEXT(chksum!G3,"00") -> 80 | H3: =TEXT(chksum!H3,"00") -> 80 | I3: =TEXT(chksum!I3,"00") -> FF | ... R3: =TEXT(chksum!R3,"00") -> FB | T3: =_xlfn.TEXTJOIN(" ", TRUE, A3:R3) -> C020 00 FF 00 00 FF 80 80 FF 00 00 FF 00 00 FF 00 00 FB
A4: =chksum!A4 -> C030 | B4: =TEXT(chksum!B4,"00") -> FF | C4: =TEXT(chksum!C4,"00") -> FF | D4: =TEXT(chksum!D4,"00") -> FF | E4: =TEXT(chksum!E4,"00") -> FF | F4: =TEXT(chksum!F4,"00") -> FC | G4: =TEXT(chksum!G4,"00") -> FC | H4: =TEXT(chksum!H4,"00") -> FF | I4: =TEXT(chksum!I4,"00") -> 00 | ... R4: =TEXT(chksum!R4,"00") -> F4 | T4: =_xlfn.TEXTJOIN(" ", TRUE, A4:R4) -> C030 FF FF FF FF FC FC FF 00 00 FF 00 00 00 00 FF 03 F4
A5: =chksum!A5 -> C040 | B5: =TEXT(chksum!B5,"00") -> 03 | C5: =TEXT(chksum!C5,"00") -> FF | D5: =TEXT(chksum!D5,"00") -> FF | E5: =TEXT(chksum!E5,"00") -> 00 | F5: =TEXT(chksum!F5,"00") -> 00 | G5: =TEXT(chksum!G5,"00") -> FF | H5: =TEXT(chksum!H5,"00") -> 00 | I5: =TEXT(chksum!I5,"00") -> 00 | ... R5: =TEXT(chksum!R5,"00") -> BF | T5: =_xlfn.TEXTJOIN(" ", TRUE, A5:R5) -> C040 03 FF FF 00 00 FF 00 00 00 00 FF 01 01 FF FF C0 BF
A6: =chksum!A6 -> C050 | B6: =TEXT(chksum!B6,"00") -> C0 | C6: =TEXT(chksum!C6,"00") -> FF | D6: =TEXT(chksum!D6,"00") -> 00 | E6: =TEXT(chksum!E6,"00") -> 00 | F6: =TEXT(chksum!F6,"00") -> 00 | G6: =TEXT(chksum!G6,"00") -> 00 | H6: =TEXT(chksum!H6,"00") -> FF | I6: =TEXT(chksum!I6,"00") -> 00 | ... R6: =TEXT(chksum!R6,"00") -> 1B | T6: =_xlfn.TEXTJOIN(" ", TRUE, A6:R6) -> C050 C0 FF 00 00 00 00 FF 00 00 FF 3F 30 F0 FF 00 00 1B
A7: =chksum!A7 -> C060 | B7: =TEXT(chksum!B7,"00") -> 00 | C7: =TEXT(chksum!C7,"00") -> 00 | D7: =TEXT(chksum!D7,"00") -> FF | E7: =TEXT(chksum!E7,"00") -> 00 | F7: =TEXT(chksum!F7,"00") -> 00 | G7: =TEXT(chksum!G7,"00") -> FF | H7: =TEXT(chksum!H7,"00") -> 1F | I7: =TEXT(chksum!I7,"00") -> 10 | ... R7: =TEXT(chksum!R7,"00") -> 1B | T7: =_xlfn.TEXTJOIN(" ", TRUE, A7:R7) -> C060 00 00 FF 00 00 FF 1F 10 F0 FF 00 00 00 00 FF 00 1B
A8: =chksum!A8 -> C070 | B8: =TEXT(chksum!B8,"00") -> 00 | C8: =TEXT(chksum!C8,"00") -> FF | D8: =TEXT(chksum!D8,"00") -> 1F | E8: =TEXT(chksum!E8,"00") -> 18 | F8: =TEXT(chksum!F8,"00") -> F8 | G8: =TEXT(chksum!G8,"00") -> FF | H8: =TEXT(chksum!H8,"00") -> 00 | I8: =TEXT(chksum!I8,"00") -> 00 | ... R8: =TEXT(chksum!R8,"00") -> 42 | T8: =_xlfn.TEXTJOIN(" ", TRUE, A8:R8) -> C070 00 FF 1F 18 F8 FF 00 00 00 00 FF 00 00 FF 0F 08 42
A9: =chksum!A9 -> C080 | B9: =TEXT(chksum!B9,"00") -> F8 | C9: =TEXT(chksum!C9,"00") -> FF | D9: =TEXT(chksum!D9,"00") -> 00 | E9: =TEXT(chksum!E9,"00") -> 00 | F9: =TEXT(chksum!F9,"00") -> 00 | G9: =TEXT(chksum!G9,"00") -> 00 | H9: =TEXT(chksum!H9,"00") -> FF | I9: =TEXT(chksum!I9,"00") -> 00 | ... R9: =TEXT(chksum!R9,"00") -> 03 | T9: =_xlfn.TEXTJOIN(" ", TRUE, A9:R9) -> C080 F8 FF 00 00 00 00 FF 00 00 FF 0F 08 F8 FF 00 00 03
A10: =chksum!A10 -> C090 | B10: =TEXT(chksum!B10,"00") -> 00 | C10: =TEXT(chksum!C10,"00") -> 00 | D10: =TEXT(chksum!D10,"00") -> FF | E10: =TEXT(chksum!E10,"00") -> 00 | F10: =TEXT(chksum!F10,"00") -> 00 | G10: =TEXT(chksum!G10,"00") -> FF | H10: =TEXT(chksum!H10,"00") -> 0F | I10: =TEXT(chksum!I10,"00") -> 08 | ... R10: =TEXT(chksum!R10,"00") -> 0B | T10: =_xlfn.TEXTJOIN(" ", TRUE, A10:R10) -> C090 00 00 FF 00 00 FF 0F 08 F8 FF 00 00 00 00 FF 00 0B
A11: =chksum!A11 -> C0A0 | B11: =TEXT(chksum!B11,"00") -> 00 | C11: =TEXT(chksum!C11,"00") -> FF | D11: =TEXT(chksum!D11,"00") -> 0F | E11: =TEXT(chksum!E11,"00") -> 08 | F11: =TEXT(chksum!F11,"00") -> F8 | G11: =TEXT(chksum!G11,"00") -> FF | H11: =TEXT(chksum!H11,"00") -> 00 | I11: =TEXT(chksum!I11,"00") -> 00 | ... R11: =TEXT(chksum!R11,"00") -> 22 | T11: =_xlfn.TEXTJOIN(" ", TRUE, A11:R11) -> C0A0 00 FF 0F 08 F8 FF 00 00 00 00 FF 00 00 FF 0F 08 22
A12: =chksum!A12 -> C0B0 | B12: =TEXT(chksum!B12,"00") -> F8 | C12: =TEXT(chksum!C12,"00") -> FF | D12: =TEXT(chksum!D12,"00") -> 00 | E12: =TEXT(chksum!E12,"00") -> 00 | F12: =TEXT(chksum!F12,"00") -> 00 | G12: =TEXT(chksum!G12,"00") -> 00 | H12: =TEXT(chksum!H12,"00") -> FF | I12: =TEXT(chksum!I12,"00") -> 00 | ... R12: =TEXT(chksum!R12,"00") -> 03 | T12: =_xlfn.TEXTJOIN(" ", TRUE, A12:R12) -> C0B0 F8 FF 00 00 00 00 FF 00 00 FF 0F 08 F8 FF 00 00 03
... A16: =chksum!A16 -> C0F0 | B16: =TEXT(chksum!B16,"00") -> FF | C16: =TEXT(chksum!C16,"00") -> 00 | D16: =TEXT(chksum!D16,"00") -> 00 | E16: =TEXT(chksum!E16,"00") -> FF | F16: =TEXT(chksum!F16,"00") -> 00 | G16: =TEXT(chksum!G16,"00") -> 00 | H16: =TEXT(chksum!H16,"00") -> FF | I16: =TEXT(chksum!I16,"00") -> 3F | ... R16: =TEXT(chksum!R16,"00") -> 76 | T16: =_xlfn.TEXTJOIN(" ", TRUE, A16:R16) -> C0F0 FF 00 00 FF 00 00 FF 3F 3F FF FF FF FF 00 00 FF 76
A17: =REPT(" ",4) | B17: =TEXT(chksum!B17,"00") -> AD | C17: =TEXT(chksum!C17,"00") -> F3 | D17: =TEXT(chksum!D17,"00") -> 27 | E17: =TEXT(chksum!E17,"00") -> 1B | F17: =TEXT(chksum!F17,"00") -> E6 | G17: =TEXT(chksum!G17,"00") -> 73 | H17: =TEXT(chksum!H17,"00") -> A5 | I17: =TEXT(chksum!I17,"00") -> 51 | ... R17: =TEXT(chksum!R17,"00") -> 98 | T17: =_xlfn.TEXTJOIN(" ", TRUE, A17:R17) -> AD F3 27 1B E6 73 A5 51 23 77 D5 3C DE F6 17 D1 98
T18: =_xlfn.TEXTJOIN(" ", TRUE, A18:R18)
A19: =chksum!A19 -> C100 | B19: =TEXT(chksum!B19,"00") -> 00 | C19: =TEXT(chksum!C19,"00") -> 00 | D19: =TEXT(chksum!D19,"00") -> FF | E19: =TEXT(chksum!E19,"00") -> C0 | F19: =TEXT(chksum!F19,"00") -> FF | G19: =TEXT(chksum!G19,"00") -> E0 | H19: =TEXT(chksum!H19,"00") -> 00 | I19: =TEXT(chksum!I19,"00") -> FF | ... R19: =TEXT(chksum!R19,"00") -> 1F | T19: =_xlfn.TEXTJOIN(" ", TRUE, A19:R19) -> C100 00 00 FF C0 FF E0 00 FF FF 00 00 FF 03 03 FE 80 1F
A20: =chksum!A20 -> C110 | B20: =TEXT(chksum!B20,"00") -> FF | C20: =TEXT(chksum!C20,"00") -> 00 | D20: =TEXT(chksum!D20,"00") -> 00 | E20: =TEXT(chksum!E20,"00") -> FF | F20: =TEXT(chksum!F20,"00") -> FF | G20: =TEXT(chksum!G20,"00") -> 00 | H20: =TEXT(chksum!H20,"00") -> 00 | I20: =TEXT(chksum!I20,"00") -> FF | ... R20: =TEXT(chksum!R20,"00") -> 05 | T20: =_xlfn.TEXTJOIN(" ", TRUE, A20:R20) -> C110 FF 00 00 FF FF 00 00 FF 0C 0F F0 00 FF 00 00 FF 05
A21: =chksum!A21 -> C120 | B21: =TEXT(chksum!B21,"00") -> FF | C21: =TEXT(chksum!C21,"00") -> 00 | D21: =TEXT(chksum!D21,"00") -> 00 | E21: =TEXT(chksum!E21,"00") -> FF | F21: =TEXT(chksum!F21,"00") -> 08 | G21: =TEXT(chksum!G21,"00") -> 0F | H21: =TEXT(chksum!H21,"00") -> E0 | I21: =TEXT(chksum!I21,"00") -> 00 | ... R21: =TEXT(chksum!R21,"00") -> F1 | T21: =_xlfn.TEXTJOIN(" ", TRUE, A21:R21) -> C120 FF 00 00 FF 08 0F E0 00 FF 00 00 FF FF 00 00 FF F1
A22: =chksum!A22 -> C130 | B22: =TEXT(chksum!B22,"00") -> 18 | C22: =TEXT(chksum!C22,"00") -> 1F | D22: =TEXT(chksum!D22,"00") -> E0 | E22: =TEXT(chksum!E22,"00") -> 00 | F22: =TEXT(chksum!F22,"00") -> FF | G22: =TEXT(chksum!G22,"00") -> 00 | H22: =TEXT(chksum!H22,"00") -> 00 | I22: =TEXT(chksum!I22,"00") -> FF | ... R22: =TEXT(chksum!R22,"00") -> 02 | T22: =_xlfn.TEXTJOIN(" ", TRUE, A22:R22) -> C130 18 1F E0 00 FF 00 00 FF FF 00 00 FF 10 1F C0 00 02
A23: =chksum!A23 -> C140 | B23: =TEXT(chksum!B23,"00") -> FF | C23: =TEXT(chksum!C23,"00") -> 00 | D23: =TEXT(chksum!D23,"00") -> 00 | E23: =TEXT(chksum!E23,"00") -> FF | F23: =TEXT(chksum!F23,"00") -> FF | G23: =TEXT(chksum!G23,"00") -> 00 | H23: =TEXT(chksum!H23,"00") -> 00 | I23: =TEXT(chksum!I23,"00") -> FF | ... R23: =TEXT(chksum!R23,"00") -> E9 | T23: =_xlfn.TEXTJOIN(" ", TRUE, A23:R23) -> C140 FF 00 00 FF FF 00 00 FF 10 1F C0 00 FF 00 00 FF E9
A24: =chksum!A24 -> C150 | B24: =TEXT(chksum!B24,"00") -> FF | C24: =TEXT(chksum!C24,"00") -> 00 | D24: =TEXT(chksum!D24,"00") -> 00 | E24: =TEXT(chksum!E24,"00") -> FF | F24: =TEXT(chksum!F24,"00") -> 10 | G24: =TEXT(chksum!G24,"00") -> 1F | H24: =TEXT(chksum!H24,"00") -> C0 | I24: =TEXT(chksum!I24,"00") -> 00 | ... R24: =TEXT(chksum!R24,"00") -> E9 | T24: =_xlfn.TEXTJOIN(" ", TRUE, A24:R24) -> C150 FF 00 00 FF 10 1F C0 00 FF 00 00 FF FF 00 00 FF E9
A25: =chksum!A25 -> C160 | B25: =TEXT(chksum!B25,"00") -> 10 | C25: =TEXT(chksum!C25,"00") -> 1F | D25: =TEXT(chksum!D25,"00") -> C0 | E25: =TEXT(chksum!E25,"00") -> 00 | F25: =TEXT(chksum!F25,"00") -> FF | G25: =TEXT(chksum!G25,"00") -> 00 | H25: =TEXT(chksum!H25,"00") -> 00 | I25: =TEXT(chksum!I25,"00") -> FF | ... R25: =TEXT(chksum!R25,"00") -> DA | T25: =_xlfn.TEXTJOIN(" ", TRUE, A25:R25) -> C160 10 1F C0 00 FF 00 00 FF FF 00 00 FF 10 1F C0 00 DA
A26: =chksum!A26 -> C170 | B26: =TEXT(chksum!B26,"00") -> FF | C26: =TEXT(chksum!C26,"00") -> 00 | D26: =TEXT(chksum!D26,"00") -> 00 | E26: =TEXT(chksum!E26,"00") -> FF | F26: =TEXT(chksum!F26,"00") -> FF | G26: =TEXT(chksum!G26,"00") -> 00 | H26: =TEXT(chksum!H26,"00") -> 00 | I26: =TEXT(chksum!I26,"00") -> FF | ... R26: =TEXT(chksum!R26,"00") -> E9 | T26: =_xlfn.TEXTJOIN(" ", TRUE, A26:R26) -> C170 FF 00 00 FF FF 00 00 FF 10 1F C0 00 FF 00 00 FF E9
A27: =chksum!A27 -> C180 | B27: =TEXT(chksum!B27,"00") -> 80 | C27: =TEXT(chksum!C27,"00") -> 80 | D27: =TEXT(chksum!D27,"00") -> 80 | E27: =TEXT(chksum!E27,"00") -> 00 | F27: =TEXT(chksum!F27,"00") -> 00 | G27: =TEXT(chksum!G27,"00") -> 00 | H27: =TEXT(chksum!H27,"00") -> 00 | I27: =TEXT(chksum!I27,"00") -> 00 | ... R27: =TEXT(chksum!R27,"00") -> C0 | T27: =_xlfn.TEXTJOIN(" ", TRUE, A27:R27) -> C180 80 80 80 00 00 00 00 00 00 00 00 00 C0 C0 C0 00 C0
A28: =chksum!A28 -> C190 | B28: =TEXT(chksum!B28,"00") -> 00 | C28: =TEXT(chksum!C28,"00") -> 00 | D28: =TEXT(chksum!D28,"00") -> 00 | E28: =TEXT(chksum!E28,"00") -> 00 | F28: =TEXT(chksum!F28,"00") -> 00 | G28: =TEXT(chksum!G28,"00") -> 00 | H28: =TEXT(chksum!H28,"00") -> 00 | I28: =TEXT(chksum!I28,"00") -> 00 | ... R28: =TEXT(chksum!R28,"00") -> A0 | T28: =_xlfn.TEXTJOIN(" ", TRUE, A28:R28) -> C190 00 00 00 00 00 00 00 00 E0 E0 E0 00 00 00 00 00 A0
A29: =chksum!A29 -> C1A0 | B29: =TEXT(chksum!B29,"00") -> 00 | C29: =TEXT(chksum!C29,"00") -> 00 | D29: =TEXT(chksum!D29,"00") -> 00 | E29: =TEXT(chksum!E29,"00") -> 00 | F29: =TEXT(chksum!F29,"00") -> 60 | G29: =TEXT(chksum!G29,"00") -> 60 | H29: =TEXT(chksum!H29,"00") -> E0 | I29: =TEXT(chksum!I29,"00") -> 00 | ... R29: =TEXT(chksum!R29,"00") -> A0 | T29: =_xlfn.TEXTJOIN(" ", TRUE, A29:R29) -> C1A0 00 00 00 00 60 60 E0 00 00 00 00 00 00 00 00 00 A0
A30: =chksum!A30 -> C1B0 | B30: =TEXT(chksum!B30,"00") -> 30 | C30: =TEXT(chksum!C30,"00") -> 30 | D30: =TEXT(chksum!D30,"00") -> F0 | E30: =TEXT(chksum!E30,"00") -> 00 | F30: =TEXT(chksum!F30,"00") -> 00 | G30: =TEXT(chksum!G30,"00") -> 00 | H30: =TEXT(chksum!H30,"00") -> 00 | I30: =TEXT(chksum!I30,"00") -> 00 | ... R30: =TEXT(chksum!R30,"00") -> B8 | T30: =_xlfn.TEXTJOIN(" ", TRUE, A30:R30) -> C1B0 30 30 F0 00 00 00 00 00 00 00 00 00 38 38 F8 00 B8
... A34: =chksum!A34 -> C1F0 | B34: =TEXT(chksum!B34,"00") -> 00 | C34: =TEXT(chksum!C34,"00") -> 00 | D34: =TEXT(chksum!D34,"00") -> 00 | E34: =TEXT(chksum!E34,"00") -> 00 | F34: =TEXT(chksum!F34,"00") -> 00 | G34: =TEXT(chksum!G34,"00") -> 00 | H34: =TEXT(chksum!H34,"00") -> 00 | I34: =TEXT(chksum!I34,"00") -> 00 | ... R34: =TEXT(chksum!R34,"00") -> 05 | T34: =_xlfn.TEXTJOIN(" ", TRUE, A34:R34) -> C1F0 00 00 00 00 00 00 00 00 03 03 FF 00 00 00 00 00 05
A35: =REPT(" ",4) | B35: =TEXT(chksum!B35,"00") -> E1 | C35: =TEXT(chksum!C35,"00") -> FC | D35: =TEXT(chksum!D35,"00") -> 0D | E35: =TEXT(chksum!E35,"00") -> BB | F35: =TEXT(chksum!F35,"00") -> 7E | G35: =TEXT(chksum!G35,"00") -> 7A | H35: =TEXT(chksum!H35,"00") -> 7C | I35: =TEXT(chksum!I35,"00") -> FA | ... R35: =TEXT(chksum!R35,"00") -> CC | T35: =_xlfn.TEXTJOIN(" ", TRUE, A35:R35) -> E1 FC 0D BB 7E 7A 7C FA 22 48 47 FB 1D 40 35 7B CC
T36: =_xlfn.TEXTJOIN(" ", TRUE, A36:R36)
A37: =chksum!A37 -> C200 | B37: =TEXT(chksum!B37,"00") -> 00 | C37: =TEXT(chksum!C37,"00") -> 00 | D37: =TEXT(chksum!D37,"00") -> 00 | E37: =TEXT(chksum!E37,"00") -> 00 | F37: =TEXT(chksum!F37,"00") -> 01 | G37: =TEXT(chksum!G37,"00") -> 01 | H37: =TEXT(chksum!H37,"00") -> FF | I37: =TEXT(chksum!I37,"00") -> 80 | ... R37: =TEXT(chksum!R37,"00") -> 81 | T37: =_xlfn.TEXTJOIN(" ", TRUE, A37:R37) -> C200 00 00 00 00 01 01 FF 80 80 80 00 00 00 00 00 00 81
A38: =chksum!A38 -> C210 | B38: =TEXT(chksum!B38,"00") -> 01 | C38: =TEXT(chksum!C38,"00") -> 01 | D38: =TEXT(chksum!D38,"00") -> FF | E38: =TEXT(chksum!E38,"00") -> C0 | F38: =TEXT(chksum!F38,"00") -> C0 | G38: =TEXT(chksum!G38,"00") -> C0 | H38: =TEXT(chksum!H38,"00") -> 00 | I38: =TEXT(chksum!I38,"00") -> 00 | ... R38: =TEXT(chksum!R38,"00") -> 20 | T38: =_xlfn.TEXTJOIN(" ", TRUE, A38:R38) -> C210 01 01 FF C0 C0 C0 00 00 00 00 00 00 00 00 FF E0 20
A39: =chksum!A39 -> C220 | B39: =TEXT(chksum!B39,"00") -> E0 | C39: =TEXT(chksum!C39,"00") -> E0 | D39: =TEXT(chksum!D39,"00") -> 00 | E39: =TEXT(chksum!E39,"00") -> 00 | F39: =TEXT(chksum!F39,"00") -> 00 | G39: =TEXT(chksum!G39,"00") -> 00 | H39: =TEXT(chksum!H39,"00") -> 00 | I39: =TEXT(chksum!I39,"00") -> 00 | ... R39: =TEXT(chksum!R39,"00") -> 5F | T39: =_xlfn.TEXTJOIN(" ", TRUE, A39:R39) -> C220 E0 E0 00 00 00 00 00 00 00 00 FF 60 60 E0 00 00 5F
A40: =chksum!A40 -> C230 | B40: =TEXT(chksum!B40,"00") -> 00 | C40: =TEXT(chksum!C40,"00") -> 00 | D40: =TEXT(chksum!D40,"00") -> 00 | E40: =TEXT(chksum!E40,"00") -> 00 | F40: =TEXT(chksum!F40,"00") -> 00 | G40: =TEXT(chksum!G40,"00") -> 00 | H40: =TEXT(chksum!H40,"00") -> FF | I40: =TEXT(chksum!I40,"00") -> 30 | ... R40: =TEXT(chksum!R40,"00") -> 4F | T40: =_xlfn.TEXTJOIN(" ", TRUE, A40:R40) -> C230 00 00 00 00 00 00 FF 30 30 F0 00 00 00 00 00 00 4F
A41: =chksum!A41 -> C240 | B41: =TEXT(chksum!B41,"00") -> 00 | C41: =TEXT(chksum!C41,"00") -> 00 | D41: =TEXT(chksum!D41,"00") -> FF | E41: =TEXT(chksum!E41,"00") -> 00 | F41: =TEXT(chksum!F41,"00") -> 00 | G41: =TEXT(chksum!G41,"00") -> FF | H41: =TEXT(chksum!H41,"00") -> 0F | I41: =TEXT(chksum!I41,"00") -> 08 | ... R41: =TEXT(chksum!R41,"00") -> 0B | T41: =_xlfn.TEXTJOIN(" ", TRUE, A41:R41) -> C240 00 00 FF 00 00 FF 0F 08 F8 FF 00 00 00 00 FF 00 0B
A42: =chksum!A42 -> C250 | B42: =TEXT(chksum!B42,"00") -> 00 | C42: =TEXT(chksum!C42,"00") -> FF | D42: =TEXT(chksum!D42,"00") -> 0F | E42: =TEXT(chksum!E42,"00") -> 08 | F42: =TEXT(chksum!F42,"00") -> F8 | G42: =TEXT(chksum!G42,"00") -> FF | H42: =TEXT(chksum!H42,"00") -> 00 | I42: =TEXT(chksum!I42,"00") -> 00 | ... R42: =TEXT(chksum!R42,"00") -> 22 | T42: =_xlfn.TEXTJOIN(" ", TRUE, A42:R42) -> C250 00 FF 0F 08 F8 FF 00 00 00 00 FF 00 00 FF 0F 08 22
A43: =chksum!A43 -> C260 | B43: =TEXT(chksum!B43,"00") -> F8 | C43: =TEXT(chksum!C43,"00") -> FF | D43: =TEXT(chksum!D43,"00") -> 00 | E43: =TEXT(chksum!E43,"00") -> 00 | F43: =TEXT(chksum!F43,"00") -> 00 | G43: =TEXT(chksum!G43,"00") -> 00 | H43: =TEXT(chksum!H43,"00") -> FF | I43: =TEXT(chksum!I43,"00") -> 00 | ... R43: =TEXT(chksum!R43,"00") -> 03 | T43: =_xlfn.TEXTJOIN(" ", TRUE, A43:R43) -> C260 F8 FF 00 00 00 00 FF 00 00 FF 0F 08 F8 FF 00 00 03
A44: =chksum!A44 -> C270 | B44: =TEXT(chksum!B44,"00") -> 00 | C44: =TEXT(chksum!C44,"00") -> 00 | D44: =TEXT(chksum!D44,"00") -> FF | E44: =TEXT(chksum!E44,"00") -> 00 | F44: =TEXT(chksum!F44,"00") -> 00 | G44: =TEXT(chksum!G44,"00") -> FF | H44: =TEXT(chksum!H44,"00") -> 0F | I44: =TEXT(chksum!I44,"00") -> 08 | ... R44: =TEXT(chksum!R44,"00") -> 0B | T44: =_xlfn.TEXTJOIN(" ", TRUE, A44:R44) -> C270 00 00 FF 00 00 FF 0F 08 F8 FF 00 00 00 00 FF 00 0B
A45: =chksum!A45 -> C280 | B45: =TEXT(chksum!B45,"00") -> 00 | C45: =TEXT(chksum!C45,"00") -> FF | D45: =TEXT(chksum!D45,"00") -> 0F | E45: =TEXT(chksum!E45,"00") -> 08 | F45: =TEXT(chksum!F45,"00") -> F8 | G45: =TEXT(chksum!G45,"00") -> FF | H45: =TEXT(chksum!H45,"00") -> 00 | I45: =TEXT(chksum!I45,"00") -> 00 | ... R45: =TEXT(chksum!R45,"00") -> 22 | T45: =_xlfn.TEXTJOIN(" ", TRUE, A45:R45) -> C280 00 FF 0F 08 F8 FF 00 00 00 00 FF 00 00 FF 0F 08 22
A46: =chksum!A46 -> C290 | B46: =TEXT(chksum!B46,"00") -> F8 | C46: =TEXT(chksum!C46,"00") -> FF | D46: =TEXT(chksum!D46,"00") -> 00 | E46: =TEXT(chksum!E46,"00") -> 00 | F46: =TEXT(chksum!F46,"00") -> 00 | G46: =TEXT(chksum!G46,"00") -> 00 | H46: =TEXT(chksum!H46,"00") -> FF | I46: =TEXT(chksum!I46,"00") -> 00 | ... R46: =TEXT(chksum!R46,"00") -> 03 | T46: =_xlfn.TEXTJOIN(" ", TRUE, A46:R46) -> C290 F8 FF 00 00 00 00 FF 00 00 FF 0F 08 F8 FF 00 00 03
...

Sheet chksum
A1: =data!A1 -> C000 | B1: =data!B1 -> FF | C1: =data!C1 -> FF | D1: =data!D1 -> FF | E1: =data!E1 -> FF | F1: =data!F1 -> FF | G1: =data!G1 -> FF | H1: =data!H1 -> FF | ... Q1: =data!Q1 -> FF | R1: =DEC2HEX(DEC!$R1,2) -> F0
A2: =data!A2 -> C010 | B2: =data!B2 -> FF | C2: =data!C2 -> FF | D2: =data!D2 -> FF | E2: =data!E2 -> FF | F2: =data!F2 -> FF | G2: =data!G2 -> FF | H2: =data!H2 -> FF | ... Q2: =data!Q2 -> 0 | R2: =DEC2HEX(DEC!$R2,2) -> F5
A3: =data!A3 -> C020 | B3: =data!B3 -> 0 | C3: =data!C3 -> FF | D3: =data!D3 -> 0 | E3: =data!E3 -> 0 | F3: =data!F3 -> FF | G3: =data!G3 -> 80 | H3: =data!H3 -> 80 | ... Q3: =data!Q3 -> 0 | R3: =DEC2HEX(DEC!$R3,2) -> FB
A4: =data!A4 -> C030 | B4: =data!B4 -> FF | C4: =data!C4 -> FF | D4: =data!D4 -> FF | E4: =data!E4 -> FF | F4: =data!F4 -> FC | G4: =data!G4 -> FC | H4: =data!H4 -> FF | ... Q4: =data!Q4 -> 3 | R4: =DEC2HEX(DEC!$R4,2) -> F4
A5: =data!A5 -> C040 | B5: =data!B5 -> 3 | C5: =data!C5 -> FF | D5: =data!D5 -> FF | E5: =data!E5 -> 0 | F5: =data!F5 -> 0 | G5: =data!G5 -> FF | H5: =data!H5 -> 0 | ... Q5: =data!Q5 -> C0 | R5: =DEC2HEX(DEC!$R5,2) -> BF
A6: =data!A6 -> C050 | B6: =data!B6 -> C0 | C6: =data!C6 -> FF | D6: =data!D6 -> 0 | E6: =data!E6 -> 0 | F6: =data!F6 -> 0 | G6: =data!G6 -> 0 | H6: =data!H6 -> FF | ... Q6: =data!Q6 -> 0 | R6: =DEC2HEX(DEC!$R6,2) -> 1B
A7: =data!A7 -> C060 | B7: =data!B7 -> 0 | C7: =data!C7 -> 0 | D7: =data!D7 -> FF | E7: =data!E7 -> 0 | F7: =data!F7 -> 0 | G7: =data!G7 -> FF | H7: =data!H7 -> 1F | ... Q7: =data!Q7 -> 0 | R7: =DEC2HEX(DEC!$R7,2) -> 1B
A8: =data!A8 -> C070 | B8: =data!B8 -> 0 | C8: =data!C8 -> FF | D8: =data!D8 -> 1F | E8: =data!E8 -> 18 | F8: =data!F8 -> F8 | G8: =data!G8 -> FF | H8: =data!H8 -> 0 | ... Q8: =data!Q8 -> 8 | R8: =DEC2HEX(DEC!$R8,2) -> 42
A9: =data!A9 -> C080 | B9: =data!B9 -> F8 | C9: =data!C9 -> FF | D9: =data!D9 -> 0 | E9: =data!E9 -> 0 | F9: =data!F9 -> 0 | G9: =data!G9 -> 0 | H9: =data!H9 -> FF | ... Q9: =data!Q9 -> 0 | R9: =DEC2HEX(DEC!$R9,2) -> 03
A10: =data!A10 -> C090 | B10: =data!B10 -> 0 | C10: =data!C10 -> 0 | D10: =data!D10 -> FF | E10: =data!E10 -> 0 | F10: =data!F10 -> 0 | G10: =data!G10 -> FF | H10: =data!H10 -> 0F | ... Q10: =data!Q10 -> 0 | R10: =DEC2HEX(DEC!$R10,2) -> 0B
A11: =data!A11 -> C0A0 | B11: =data!B11 -> 0 | C11: =data!C11 -> FF | D11: =data!D11 -> 0F | E11: =data!E11 -> 8 | F11: =data!F11 -> F8 | G11: =data!G11 -> FF | H11: =data!H11 -> 0 | ... Q11: =data!Q11 -> 8 | R11: =DEC2HEX(DEC!$R11,2) -> 22
A12: =data!A12 -> C0B0 | B12: =data!B12 -> F8 | C12: =data!C12 -> FF | D12: =data!D12 -> 0 | E12: =data!E12 -> 0 | F12: =data!F12 -> 0 | G12: =data!G12 -> 0 | H12: =data!H12 -> FF | ... Q12: =data!Q12 -> 0 | R12: =DEC2HEX(DEC!$R12,2) -> 03
... A16: =data!A16 -> C0F0 | B16: =data!B16 -> FF | C16: =data!C16 -> 0 | D16: =data!D16 -> 0 | E16: =data!E16 -> FF | F16: =data!F16 -> 0 | G16: =data!G16 -> 0 | H16: =data!H16 -> FF | ... Q16: =data!Q16 -> FF | R16: =DEC2HEX(DEC!$R16,2) -> 76
B17: =DEC2HEX(DEC!B17,2) -> AD | C17: =DEC2HEX(DEC!C17,2) -> F3 | D17: =DEC2HEX(DEC!D17,2) -> 27 | E17: =DEC2HEX(DEC!E17,2) -> 1B | F17: =DEC2HEX(DEC!F17,2) -> E6 | G17: =DEC2HEX(DEC!G17,2) -> 73 | H17: =DEC2HEX(DEC!H17,2) -> A5 | I17: =DEC2HEX(DEC!I17,2) -> 51 | ... R17: =DEC2HEX(DEC!R17,2) -> 98
A19: =data!A19 -> C100 | B19: =data!B19 -> 0 | C19: =data!C19 -> 0 | D19: =data!D19 -> FF | E19: =data!E19 -> C0 | F19: =data!F19 -> FF | G19: =data!G19 -> E0 | H19: =data!H19 -> 0 | ... Q19: =data!Q19 -> 80 | R19: =DEC2HEX(DEC!$R19) -> 1F
A20: =data!A20 -> C110 | B20: =data!B20 -> FF | C20: =data!C20 -> 0 | D20: =data!D20 -> 0 | E20: =data!E20 -> FF | F20: =data!F20 -> FF | G20: =data!G20 -> 0 | H20: =data!H20 -> 0 | ... Q20: =data!Q20 -> FF | R20: =DEC2HEX(DEC!$R20) -> 5
A21: =data!A21 -> C120 | B21: =data!B21 -> FF | C21: =data!C21 -> 0 | D21: =data!D21 -> 0 | E21: =data!E21 -> FF | F21: =data!F21 -> 8 | G21: =data!G21 -> 0F | H21: =data!H21 -> E0 | ... Q21: =data!Q21 -> FF | R21: =DEC2HEX(DEC!$R21) -> F1
A22: =data!A22 -> C130 | B22: =data!B22 -> 18 | C22: =data!C22 -> 1F | D22: =data!D22 -> E0 | E22: =data!E22 -> 0 | F22: =data!F22 -> FF | G22: =data!G22 -> 0 | H22: =data!H22 -> 0 | ... Q22: =data!Q22 -> 0 | R22: =DEC2HEX(DEC!$R22) -> 2
A23: =data!A23 -> C140 | B23: =data!B23 -> FF | C23: =data!C23 -> 0 | D23: =data!D23 -> 0 | E23: =data!E23 -> FF | F23: =data!F23 -> FF | G23: =data!G23 -> 0 | H23: =data!H23 -> 0 | ... Q23: =data!Q23 -> FF | R23: =DEC2HEX(DEC!$R23) -> E9
A24: =data!A24 -> C150 | B24: =data!B24 -> FF | C24: =data!C24 -> 0 | D24: =data!D24 -> 0 | E24: =data!E24 -> FF | F24: =data!F24 -> 10 | G24: =data!G24 -> 1F | H24: =data!H24 -> C0 | ... Q24: =data!Q24 -> FF | R24: =DEC2HEX(DEC!$R24) -> E9
A25: =data!A25 -> C160 | B25: =data!B25 -> 10 | C25: =data!C25 -> 1F | D25: =data!D25 -> C0 | E25: =data!E25 -> 0 | F25: =data!F25 -> FF | G25: =data!G25 -> 0 | H25: =data!H25 -> 0 | ... Q25: =data!Q25 -> 0 | R25: =DEC2HEX(DEC!$R25) -> DA
A26: =data!A26 -> C170 | B26: =data!B26 -> FF | C26: =data!C26 -> 0 | D26: =data!D26 -> 0 | E26: =data!E26 -> FF | F26: =data!F26 -> FF | G26: =data!G26 -> 0 | H26: =data!H26 -> 0 | ... Q26: =data!Q26 -> FF | R26: =DEC2HEX(DEC!$R26) -> E9
A27: =data!A27 -> C180 | B27: =data!B27 -> 80 | C27: =data!C27 -> 80 | D27: =data!D27 -> 80 | E27: =data!E27 -> 0 | F27: =data!F27 -> 0 | G27: =data!G27 -> 0 | H27: =data!H27 -> 0 | ... Q27: =data!Q27 -> 0 | R27: =DEC2HEX(DEC!$R27) -> C0
A28: =data!A28 -> C190 | B28: =data!B28 -> 0 | C28: =data!C28 -> 0 | D28: =data!D28 -> 0 | E28: =data!E28 -> 0 | F28: =data!F28 -> 0 | G28: =data!G28 -> 0 | H28: =data!H28 -> 0 | ... Q28: =data!Q28 -> 0 | R28: =DEC2HEX(DEC!$R28) -> A0
A29: =data!A29 -> C1A0 | B29: =data!B29 -> 0 | C29: =data!C29 -> 0 | D29: =data!D29 -> 0 | E29: =data!E29 -> 0 | F29: =data!F29 -> 60 | G29: =data!G29 -> 60 | H29: =data!H29 -> E0 | ... Q29: =data!Q29 -> 0 | R29: =DEC2HEX(DEC!$R29) -> A0
A30: =data!A30 -> C1B0 | B30: =data!B30 -> 30 | C30: =data!C30 -> 30 | D30: =data!D30 -> F0 | E30: =data!E30 -> 0 | F30: =data!F30 -> 0 | G30: =data!G30 -> 0 | H30: =data!H30 -> 0 | ... Q30: =data!Q30 -> 0 | R30: =DEC2HEX(DEC!$R30) -> B8
... A34: =data!A34 -> C1F0 | B34: =data!B34 -> 0 | C34: =data!C34 -> 0 | D34: =data!D34 -> 0 | E34: =data!E34 -> 0 | F34: =data!F34 -> 0 | G34: =data!G34 -> 0 | H34: =data!H34 -> 0 | ... Q34: =data!Q34 -> 0 | R34: =DEC2HEX(DEC!$R34) -> 5
B35: =DEC2HEX(DEC!B35,2) -> E1 | C35: =DEC2HEX(DEC!C35,2) -> FC | D35: =DEC2HEX(DEC!D35,2) -> 0D | E35: =DEC2HEX(DEC!E35,2) -> BB | F35: =DEC2HEX(DEC!F35,2) -> 7E | G35: =DEC2HEX(DEC!G35,2) -> 7A | H35: =DEC2HEX(DEC!H35,2) -> 7C | I35: =DEC2HEX(DEC!I35,2) -> FA | ... R35: =DEC2HEX(DEC!R35,2) -> CC
A37: =data!A37 -> C200 | B37: =data!B37 -> 0 | C37: =data!C37 -> 0 | D37: =data!D37 -> 0 | E37: =data!E37 -> 0 | F37: =data!F37 -> 1 | G37: =data!G37 -> 1 | H37: =data!H37 -> FF | ... Q37: =data!Q37 -> 0 | R37: =DEC2HEX(DEC!$R37,2) -> 81
A38: =data!A38 -> C210 | B38: =data!B38 -> 1 | C38: =data!C38 -> 1 | D38: =data!D38 -> FF | E38: =data!E38 -> C0 | F38: =data!F38 -> C0 | G38: =data!G38 -> C0 | H38: =data!H38 -> 0 | ... Q38: =data!Q38 -> E0 | R38: =DEC2HEX(DEC!$R38,2) -> 20
A39: =data!A39 -> C220 | B39: =data!B39 -> E0 | C39: =data!C39 -> E0 | D39: =data!D39 -> 0 | E39: =data!E39 -> 0 | F39: =data!F39 -> 0 | G39: =data!G39 -> 0 | H39: =data!H39 -> 0 | ... Q39: =data!Q39 -> 0 | R39: =DEC2HEX(DEC!$R39,2) -> 5F
A40: =data!A40 -> C230 | B40: =data!B40 -> 0 | C40: =data!C40 -> 0 | D40: =data!D40 -> 0 | E40: =data!E40 -> 0 | F40: =data!F40 -> 0 | G40: =data!G40 -> 0 | H40: =data!H40 -> FF | ... Q40: =data!Q40 -> 0 | R40: =DEC2HEX(DEC!$R40,2) -> 4F
A41: =data!A41 -> C240 | B41: =data!B41 -> 0 | C41: =data!C41 -> 0 | D41: =data!D41 -> FF | E41: =data!E41 -> 0 | F41: =data!F41 -> 0 | G41: =data!G41 -> FF | H41: =data!H41 -> 0F | ... Q41: =data!Q41 -> 0 | R41: =DEC2HEX(DEC!$R41,2) -> 0B
A42: =data!A42 -> C250 | B42: =data!B42 -> 0 | C42: =data!C42 -> FF | D42: =data!D42 -> 0F | E42: =data!E42 -> 8 | F42: =data!F42 -> F8 | G42: =data!G42 -> FF | H42: =data!H42 -> 0 | ... Q42: =data!Q42 -> 8 | R42: =DEC2HEX(DEC!$R42,2) -> 22
A43: =data!A43 -> C260 | B43: =data!B43 -> F8 | C43: =data!C43 -> FF | D43: =data!D43 -> 0 | E43: =data!E43 -> 0 | F43: =data!F43 -> 0 | G43: =data!G43 -> 0 | H43: =data!H43 -> FF | ... Q43: =data!Q43 -> 0 | R43: =DEC2HEX(DEC!$R43,2) -> 03
A44: =data!A44 -> C270 | B44: =data!B44 -> 0 | C44: =data!C44 -> 0 | D44: =data!D44 -> FF | E44: =data!E44 -> 0 | F44: =data!F44 -> 0 | G44: =data!G44 -> FF | H44: =data!H44 -> 0F | ... Q44: =data!Q44 -> 0 | R44: =DEC2HEX(DEC!$R44,2) -> 0B
A45: =data!A45 -> C280 | B45: =data!B45 -> 0 | C45: =data!C45 -> FF | D45: =data!D45 -> 0F | E45: =data!E45 -> 8 | F45: =data!F45 -> F8 | G45: =data!G45 -> FF | H45: =data!H45 -> 0 | ... Q45: =data!Q45 -> 8 | R45: =DEC2HEX(DEC!$R45,2) -> 22
A46: =data!A46 -> C290 | B46: =data!B46 -> F8 | C46: =data!C46 -> FF | D46: =data!D46 -> 0 | E46: =data!E46 -> 0 | F46: =data!F46 -> 0 | G46: =data!G46 -> 0 | H46: =data!H46 -> FF | ... Q46: =data!Q46 -> 0 | R46: =DEC2HEX(DEC!$R46,2) -> 03
A47: =data!A47 -> C2A0 | B47: =data!B47 -> 0 | C47: =data!C47 -> 0 | D47: =data!D47 -> FF | E47: =data!E47 -> 0 | F47: =data!F47 -> 0 | G47: =data!G47 -> FF | H47: =data!H47 -> 0F | ... Q47: =data!Q47 -> 0 | R47: =DEC2HEX(DEC!$R47,2) -> 0B
A48: =data!A48 -> C2B0 | B48: =data!B48 -> 0 | C48: =data!C48 -> FF | D48: =data!D48 -> 0F | E48: =data!E48 -> 8 | F48: =data!F48 -> F8 | G48: =data!G48 -> FF | H48: =data!H48 -> 0 | ... Q48: =data!Q48 -> 8 | R48: =DEC2HEX(DEC!$R48,2) -> 22
...

Sheet DEC
A1: =data!A1 -> C000 | B1: =HEX2DEC(data!B1) -> 255 | C1: =HEX2DEC(data!C1) -> 255 | D1: =HEX2DEC(data!D1) -> 255 | E1: =HEX2DEC(data!E1) -> 255 | F1: =HEX2DEC(data!F1) -> 255 | G1: =HEX2DEC(data!G1) -> 255 | H1: =HEX2DEC(data!H1) -> 255 | I1: =HEX2DEC(data!I1) -> 255 | ... Q1: =HEX2DEC(data!Q1) -> 255 | R1: =MOD(SUM(B1:Q1),256) -> 240
A2: =data!A2 -> C010 | B2: =HEX2DEC(data!B2) -> 255 | C2: =HEX2DEC(data!C2) -> 255 | D2: =HEX2DEC(data!D2) -> 255 | E2: =HEX2DEC(data!E2) -> 255 | F2: =HEX2DEC(data!F2) -> 255 | G2: =HEX2DEC(data!G2) -> 255 | H2: =HEX2DEC(data!H2) -> 255 | I2: =HEX2DEC(data!I2) -> 255 | ... Q2: =HEX2DEC(data!Q2) -> 0 | R2: =MOD(SUM(B2:Q2),256) -> 245
A3: =data!A3 -> C020 | B3: =HEX2DEC(data!B3) -> 0 | C3: =HEX2DEC(data!C3) -> 255 | D3: =HEX2DEC(data!D3) -> 0 | E3: =HEX2DEC(data!E3) -> 0 | F3: =HEX2DEC(data!F3) -> 255 | G3: =HEX2DEC(data!G3) -> 128 | H3: =HEX2DEC(data!H3) -> 128 | I3: =HEX2DEC(data!I3) -> 255 | ... Q3: =HEX2DEC(data!Q3) -> 0 | R3: =MOD(SUM(B3:Q3),256) -> 251
A4: =data!A4 -> C030 | B4: =HEX2DEC(data!B4) -> 255 | C4: =HEX2DEC(data!C4) -> 255 | D4: =HEX2DEC(data!D4) -> 255 | E4: =HEX2DEC(data!E4) -> 255 | F4: =HEX2DEC(data!F4) -> 252 | G4: =HEX2DEC(data!G4) -> 252 | H4: =HEX2DEC(data!H4) -> 255 | I4: =HEX2DEC(data!I4) -> 0 | ... Q4: =HEX2DEC(data!Q4) -> 3 | R4: =MOD(SUM(B4:Q4),256) -> 244
A5: =data!A5 -> C040 | B5: =HEX2DEC(data!B5) -> 3 | C5: =HEX2DEC(data!C5) -> 255 | D5: =HEX2DEC(data!D5) -> 255 | E5: =HEX2DEC(data!E5) -> 0 | F5: =HEX2DEC(data!F5) -> 0 | G5: =HEX2DEC(data!G5) -> 255 | H5: =HEX2DEC(data!H5) -> 0 | I5: =HEX2DEC(data!I5) -> 0 | ... Q5: =HEX2DEC(data!Q5) -> 192 | R5: =MOD(SUM(B5:Q5),256) -> 191
A6: =data!A6 -> C050 | B6: =HEX2DEC(data!B6) -> 192 | C6: =HEX2DEC(data!C6) -> 255 | D6: =HEX2DEC(data!D6) -> 0 | E6: =HEX2DEC(data!E6) -> 0 | F6: =HEX2DEC(data!F6) -> 0 | G6: =HEX2DEC(data!G6) -> 0 | H6: =HEX2DEC(data!H6) -> 255 | I6: =HEX2DEC(data!I6) -> 0 | ... Q6: =HEX2DEC(data!Q6) -> 0 | R6: =MOD(SUM(B6:Q6),256) -> 27
A7: =data!A7 -> C060 | B7: =HEX2DEC(data!B7) -> 0 | C7: =HEX2DEC(data!C7) -> 0 | D7: =HEX2DEC(data!D7) -> 255 | E7: =HEX2DEC(data!E7) -> 0 | F7: =HEX2DEC(data!F7) -> 0 | G7: =HEX2DEC(data!G7) -> 255 | H7: =HEX2DEC(data!H7) -> 31 | I7: =HEX2DEC(data!I7) -> 16 | ... Q7: =HEX2DEC(data!Q7) -> 0 | R7: =MOD(SUM(B7:Q7),256) -> 27
A8: =data!A8 -> C070 | B8: =HEX2DEC(data!B8) -> 0 | C8: =HEX2DEC(data!C8) -> 255 | D8: =HEX2DEC(data!D8) -> 31 | E8: =HEX2DEC(data!E8) -> 24 | F8: =HEX2DEC(data!F8) -> 248 | G8: =HEX2DEC(data!G8) -> 255 | H8: =HEX2DEC(data!H8) -> 0 | I8: =HEX2DEC(data!I8) -> 0 | ... Q8: =HEX2DEC(data!Q8) -> 8 | R8: =MOD(SUM(B8:Q8),256) -> 66
A9: =data!A9 -> C080 | B9: =HEX2DEC(data!B9) -> 248 | C9: =HEX2DEC(data!C9) -> 255 | D9: =HEX2DEC(data!D9) -> 0 | E9: =HEX2DEC(data!E9) -> 0 | F9: =HEX2DEC(data!F9) -> 0 | G9: =HEX2DEC(data!G9) -> 0 | H9: =HEX2DEC(data!H9) -> 255 | I9: =HEX2DEC(data!I9) -> 0 | ... Q9: =HEX2DEC(data!Q9) -> 0 | R9: =MOD(SUM(B9:Q9),256) -> 3
A10: =data!A10 -> C090 | B10: =HEX2DEC(data!B10) -> 0 | C10: =HEX2DEC(data!C10) -> 0 | D10: =HEX2DEC(data!D10) -> 255 | E10: =HEX2DEC(data!E10) -> 0 | F10: =HEX2DEC(data!F10) -> 0 | G10: =HEX2DEC(data!G10) -> 255 | H10: =HEX2DEC(data!H10) -> 15 | I10: =HEX2DEC(data!I10) -> 8 | ... Q10: =HEX2DEC(data!Q10) -> 0 | R10: =MOD(SUM(B10:Q10),256) -> 11
A11: =data!A11 -> C0A0 | B11: =HEX2DEC(data!B11) -> 0 | C11: =HEX2DEC(data!C11) -> 255 | D11: =HEX2DEC(data!D11) -> 15 | E11: =HEX2DEC(data!E11) -> 8 | F11: =HEX2DEC(data!F11) -> 248 | G11: =HEX2DEC(data!G11) -> 255 | H11: =HEX2DEC(data!H11) -> 0 | I11: =HEX2DEC(data!I11) -> 0 | ... Q11: =HEX2DEC(data!Q11) -> 8 | R11: =MOD(SUM(B11:Q11),256) -> 34
A12: =data!A12 -> C0B0 | B12: =HEX2DEC(data!B12) -> 248 | C12: =HEX2DEC(data!C12) -> 255 | D12: =HEX2DEC(data!D12) -> 0 | E12: =HEX2DEC(data!E12) -> 0 | F12: =HEX2DEC(data!F12) -> 0 | G12: =HEX2DEC(data!G12) -> 0 | H12: =HEX2DEC(data!H12) -> 255 | I12: =HEX2DEC(data!I12) -> 0 | ... Q12: =HEX2DEC(data!Q12) -> 0 | R12: =MOD(SUM(B12:Q12),256) -> 3
... A16: =data!A16 -> C0F0 | B16: =HEX2DEC(data!B16) -> 255 | C16: =HEX2DEC(data!C16) -> 0 | D16: =HEX2DEC(data!D16) -> 0 | E16: =HEX2DEC(data!E16) -> 255 | F16: =HEX2DEC(data!F16) -> 0 | G16: =HEX2DEC(data!G16) -> 0 | H16: =HEX2DEC(data!H16) -> 255 | I16: =HEX2DEC(data!I16) -> 63 | ... Q16: =HEX2DEC(data!Q16) -> 255 | R16: =MOD(SUM(B16:Q16),256) -> 118
B17: =MOD(SUM(B1:B16),256) -> 173 | C17: =MOD(SUM(C1:C16),256) -> 243 | D17: =MOD(SUM(D1:D16),256) -> 39 | E17: =MOD(SUM(E1:E16),256) -> 27 | F17: =MOD(SUM(F1:F16),256) -> 230 | G17: =MOD(SUM(G1:G16),256) -> 115 | H17: =MOD(SUM(H1:H16),256) -> 165 | I17: =MOD(SUM(I1:I16),256) -> 81 | ... R17: =MOD(SUM(R1:R16),256) -> 152
A19: =data!A19 -> C100 | B19: =HEX2DEC(data!B19) -> 0 | C19: =HEX2DEC(data!C19) -> 0 | D19: =HEX2DEC(data!D19) -> 255 | E19: =HEX2DEC(data!E19) -> 192 | F19: =HEX2DEC(data!F19) -> 255 | G19: =HEX2DEC(data!G19) -> 224 | H19: =HEX2DEC(data!H19) -> 0 | I19: =HEX2DEC(data!I19) -> 255 | ... Q19: =HEX2DEC(data!Q19) -> 128 | R19: =MOD(SUM(B19:Q19),256) -> 31
A20: =data!A20 -> C110 | B20: =HEX2DEC(data!B20) -> 255 | C20: =HEX2DEC(data!C20) -> 0 | D20: =HEX2DEC(data!D20) -> 0 | E20: =HEX2DEC(data!E20) -> 255 | F20: =HEX2DEC(data!F20) -> 255 | G20: =HEX2DEC(data!G20) -> 0 | H20: =HEX2DEC(data!H20) -> 0 | I20: =HEX2DEC(data!I20) -> 255 | ... Q20: =HEX2DEC(data!Q20) -> 255 | R20: =MOD(SUM(B20:Q20),256) -> 5
A21: =data!A21 -> C120 | B21: =HEX2DEC(data!B21) -> 255 | C21: =HEX2DEC(data!C21) -> 0 | D21: =HEX2DEC(data!D21) -> 0 | E21: =HEX2DEC(data!E21) -> 255 | F21: =HEX2DEC(data!F21) -> 8 | G21: =HEX2DEC(data!G21) -> 15 | H21: =HEX2DEC(data!H21) -> 224 | I21: =HEX2DEC(data!I21) -> 0 | ... Q21: =HEX2DEC(data!Q21) -> 255 | R21: =MOD(SUM(B21:Q21),256) -> 241
A22: =data!A22 -> C130 | B22: =HEX2DEC(data!B22) -> 24 | C22: =HEX2DEC(data!C22) -> 31 | D22: =HEX2DEC(data!D22) -> 224 | E22: =HEX2DEC(data!E22) -> 0 | F22: =HEX2DEC(data!F22) -> 255 | G22: =HEX2DEC(data!G22) -> 0 | H22: =HEX2DEC(data!H22) -> 0 | I22: =HEX2DEC(data!I22) -> 255 | ... Q22: =HEX2DEC(data!Q22) -> 0 | R22: =MOD(SUM(B22:Q22),256) -> 2
A23: =data!A23 -> C140 | B23: =HEX2DEC(data!B23) -> 255 | C23: =HEX2DEC(data!C23) -> 0 | D23: =HEX2DEC(data!D23) -> 0 | E23: =HEX2DEC(data!E23) -> 255 | F23: =HEX2DEC(data!F23) -> 255 | G23: =HEX2DEC(data!G23) -> 0 | H23: =HEX2DEC(data!H23) -> 0 | I23: =HEX2DEC(data!I23) -> 255 | ... Q23: =HEX2DEC(data!Q23) -> 255 | R23: =MOD(SUM(B23:Q23),256) -> 233
A24: =data!A24 -> C150 | B24: =HEX2DEC(data!B24) -> 255 | C24: =HEX2DEC(data!C24) -> 0 | D24: =HEX2DEC(data!D24) -> 0 | E24: =HEX2DEC(data!E24) -> 255 | F24: =HEX2DEC(data!F24) -> 16 | G24: =HEX2DEC(data!G24) -> 31 | H24: =HEX2DEC(data!H24) -> 192 | I24: =HEX2DEC(data!I24) -> 0 | ... Q24: =HEX2DEC(data!Q24) -> 255 | R24: =MOD(SUM(B24:Q24),256) -> 233
A25: =data!A25 -> C160 | B25: =HEX2DEC(data!B25) -> 16 | C25: =HEX2DEC(data!C25) -> 31 | D25: =HEX2DEC(data!D25) -> 192 | E25: =HEX2DEC(data!E25) -> 0 | F25: =HEX2DEC(data!F25) -> 255 | G25: =HEX2DEC(data!G25) -> 0 | H25: =HEX2DEC(data!H25) -> 0 | I25: =HEX2DEC(data!I25) -> 255 | ... Q25: =HEX2DEC(data!Q25) -> 0 | R25: =MOD(SUM(B25:Q25),256) -> 218
A26: =data!A26 -> C170 | B26: =HEX2DEC(data!B26) -> 255 | C26: =HEX2DEC(data!C26) -> 0 | D26: =HEX2DEC(data!D26) -> 0 | E26: =HEX2DEC(data!E26) -> 255 | F26: =HEX2DEC(data!F26) -> 255 | G26: =HEX2DEC(data!G26) -> 0 | H26: =HEX2DEC(data!H26) -> 0 | I26: =HEX2DEC(data!I26) -> 255 | ... Q26: =HEX2DEC(data!Q26) -> 255 | R26: =MOD(SUM(B26:Q26),256) -> 233
A27: =data!A27 -> C180 | B27: =HEX2DEC(data!B27) -> 128 | C27: =HEX2DEC(data!C27) -> 128 | D27: =HEX2DEC(data!D27) -> 128 | E27: =HEX2DEC(data!E27) -> 0 | F27: =HEX2DEC(data!F27) -> 0 | G27: =HEX2DEC(data!G27) -> 0 | H27: =HEX2DEC(data!H27) -> 0 | I27: =HEX2DEC(data!I27) -> 0 | ... Q27: =HEX2DEC(data!Q27) -> 0 | R27: =MOD(SUM(B27:Q27),256) -> 192
A28: =data!A28 -> C190 | B28: =HEX2DEC(data!B28) -> 0 | C28: =HEX2DEC(data!C28) -> 0 | D28: =HEX2DEC(data!D28) -> 0 | E28: =HEX2DEC(data!E28) -> 0 | F28: =HEX2DEC(data!F28) -> 0 | G28: =HEX2DEC(data!G28) -> 0 | H28: =HEX2DEC(data!H28) -> 0 | I28: =HEX2DEC(data!I28) -> 0 | ... Q28: =HEX2DEC(data!Q28) -> 0 | R28: =MOD(SUM(B28:Q28),256) -> 160
A29: =data!A29 -> C1A0 | B29: =HEX2DEC(data!B29) -> 0 | C29: =HEX2DEC(data!C29) -> 0 | D29: =HEX2DEC(data!D29) -> 0 | E29: =HEX2DEC(data!E29) -> 0 | F29: =HEX2DEC(data!F29) -> 96 | G29: =HEX2DEC(data!G29) -> 96 | H29: =HEX2DEC(data!H29) -> 224 | I29: =HEX2DEC(data!I29) -> 0 | ... Q29: =HEX2DEC(data!Q29) -> 0 | R29: =MOD(SUM(B29:Q29),256) -> 160
A30: =data!A30 -> C1B0 | B30: =HEX2DEC(data!B30) -> 48 | C30: =HEX2DEC(data!C30) -> 48 | D30: =HEX2DEC(data!D30) -> 240 | E30: =HEX2DEC(data!E30) -> 0 | F30: =HEX2DEC(data!F30) -> 0 | G30: =HEX2DEC(data!G30) -> 0 | H30: =HEX2DEC(data!H30) -> 0 | I30: =HEX2DEC(data!I30) -> 0 | ... Q30: =HEX2DEC(data!Q30) -> 0 | R30: =MOD(SUM(B30:Q30),256) -> 184
... A34: =data!A34 -> C1F0 | B34: =HEX2DEC(data!B34) -> 0 | C34: =HEX2DEC(data!C34) -> 0 | D34: =HEX2DEC(data!D34) -> 0 | E34: =HEX2DEC(data!E34) -> 0 | F34: =HEX2DEC(data!F34) -> 0 | G34: =HEX2DEC(data!G34) -> 0 | H34: =HEX2DEC(data!H34) -> 0 | I34: =HEX2DEC(data!I34) -> 0 | ... Q34: =HEX2DEC(data!Q34) -> 0 | R34: =MOD(SUM(B34:Q34),256) -> 5
B35: =MOD(SUM(B19:B34),256) -> 225 | C35: =MOD(SUM(C19:C34),256) -> 252 | D35: =MOD(SUM(D19:D34),256) -> 13 | E35: =MOD(SUM(E19:E34),256) -> 187 | F35: =MOD(SUM(F19:F34),256) -> 126 | G35: =MOD(SUM(G19:G34),256) -> 122 | H35: =MOD(SUM(H19:H34),256) -> 124 | I35: =MOD(SUM(I19:I34),256) -> 250 | ... R35: =MOD(SUM(R19:R34),256) -> 204
A37: =data!A37 -> C200 | B37: =HEX2DEC(data!B37) -> 0 | C37: =HEX2DEC(data!C37) -> 0 | D37: =HEX2DEC(data!D37) -> 0 | E37: =HEX2DEC(data!E37) -> 0 | F37: =HEX2DEC(data!F37) -> 1 | G37: =HEX2DEC(data!G37) -> 1 | H37: =HEX2DEC(data!H37) -> 255 | I37: =HEX2DEC(data!I37) -> 128 | ... Q37: =HEX2DEC(data!Q37) -> 0 | R37: =MOD(SUM(B37:Q37),256) -> 129
A38: =data!A38 -> C210 | B38: =HEX2DEC(data!B38) -> 1 | C38: =HEX2DEC(data!C38) -> 1 | D38: =HEX2DEC(data!D38) -> 255 | E38: =HEX2DEC(data!E38) -> 192 | F38: =HEX2DEC(data!F38) -> 192 | G38: =HEX2DEC(data!G38) -> 192 | H38: =HEX2DEC(data!H38) -> 0 | I38: =HEX2DEC(data!I38) -> 0 | ... Q38: =HEX2DEC(data!Q38) -> 224 | R38: =MOD(SUM(B38:Q38),256) -> 32
A39: =data!A39 -> C220 | B39: =HEX2DEC(data!B39) -> 224 | C39: =HEX2DEC(data!C39) -> 224 | D39: =HEX2DEC(data!D39) -> 0 | E39: =HEX2DEC(data!E39) -> 0 | F39: =HEX2DEC(data!F39) -> 0 | G39: =HEX2DEC(data!G39) -> 0 | H39: =HEX2DEC(data!H39) -> 0 | I39: =HEX2DEC(data!I39) -> 0 | ... Q39: =HEX2DEC(data!Q39) -> 0 | R39: =MOD(SUM(B39:Q39),256) -> 95
A40: =data!A40 -> C230 | B40: =HEX2DEC(data!B40) -> 0 | C40: =HEX2DEC(data!C40) -> 0 | D40: =HEX2DEC(data!D40) -> 0 | E40: =HEX2DEC(data!E40) -> 0 | F40: =HEX2DEC(data!F40) -> 0 | G40: =HEX2DEC(data!G40) -> 0 | H40: =HEX2DEC(data!H40) -> 255 | I40: =HEX2DEC(data!I40) -> 48 | ... Q40: =HEX2DEC(data!Q40) -> 0 | R40: =MOD(SUM(B40:Q40),256) -> 79
A41: =data!A41 -> C240 | B41: =HEX2DEC(data!B41) -> 0 | C41: =HEX2DEC(data!C41) -> 0 | D41: =HEX2DEC(data!D41) -> 255 | E41: =HEX2DEC(data!E41) -> 0 | F41: =HEX2DEC(data!F41) -> 0 | G41: =HEX2DEC(data!G41) -> 255 | H41: =HEX2DEC(data!H41) -> 15 | I41: =HEX2DEC(data!I41) -> 8 | ... Q41: =HEX2DEC(data!Q41) -> 0 | R41: =MOD(SUM(B41:Q41),256) -> 11
A42: =data!A42 -> C250 | B42: =HEX2DEC(data!B42) -> 0 | C42: =HEX2DEC(data!C42) -> 255 | D42: =HEX2DEC(data!D42) -> 15 | E42: =HEX2DEC(data!E42) -> 8 | F42: =HEX2DEC(data!F42) -> 248 | G42: =HEX2DEC(data!G42) -> 255 | H42: =HEX2DEC(data!H42) -> 0 | I42: =HEX2DEC(data!I42) -> 0 | ... Q42: =HEX2DEC(data!Q42) -> 8 | R42: =MOD(SUM(B42:Q42),256) -> 34
A43: =data!A43 -> C260 | B43: =HEX2DEC(data!B43) -> 248 | C43: =HEX2DEC(data!C43) -> 255 | D43: =HEX2DEC(data!D43) -> 0 | E43: =HEX2DEC(data!E43) -> 0 | F43: =HEX2DEC(data!F43) -> 0 | G43: =HEX2DEC(data!G43) -> 0 | H43: =HEX2DEC(data!H43) -> 255 | I43: =HEX2DEC(data!I43) -> 0 | ... Q43: =HEX2DEC(data!Q43) -> 0 | R43: =MOD(SUM(B43:Q43),256) -> 3
A44: =data!A44 -> C270 | B44: =HEX2DEC(data!B44) -> 0 | C44: =HEX2DEC(data!C44) -> 0 | D44: =HEX2DEC(data!D44) -> 255 | E44: =HEX2DEC(data!E44) -> 0 | F44: =HEX2DEC(data!F44) -> 0 | G44: =HEX2DEC(data!G44) -> 255 | H44: =HEX2DEC(data!H44) -> 15 | I44: =HEX2DEC(data!I44) -> 8 | ... Q44: =HEX2DEC(data!Q44) -> 0 | R44: =MOD(SUM(B44:Q44),256) -> 11
A45: =data!A45 -> C280 | B45: =HEX2DEC(data!B45) -> 0 | C45: =HEX2DEC(data!C45) -> 255 | D45: =HEX2DEC(data!D45) -> 15 | E45: =HEX2DEC(data!E45) -> 8 | F45: =HEX2DEC(data!F45) -> 248 | G45: =HEX2DEC(data!G45) -> 255 | H45: =HEX2DEC(data!H45) -> 0 | I45: =HEX2DEC(data!I45) -> 0 | ... Q45: =HEX2DEC(data!Q45) -> 8 | R45: =MOD(SUM(B45:Q45),256) -> 34
A46: =data!A46 -> C290 | B46: =HEX2DEC(data!B46) -> 248 | C46: =HEX2DEC(data!C46) -> 255 | D46: =HEX2DEC(data!D46) -> 0 | E46: =HEX2DEC(data!E46) -> 0 | F46: =HEX2DEC(data!F46) -> 0 | G46: =HEX2DEC(data!G46) -> 0 | H46: =HEX2DEC(data!H46) -> 255 | I46: =HEX2DEC(data!I46) -> 0 | ... Q46: =HEX2DEC(data!Q46) -> 0 | R46: =MOD(SUM(B46:Q46),256) -> 3
A47: =data!A47 -> C2A0 | B47: =HEX2DEC(data!B47) -> 0 | C47: =HEX2DEC(data!C47) -> 0 | D47: =HEX2DEC(data!D47) -> 255 | E47: =HEX2DEC(data!E47) -> 0 | F47: =HEX2DEC(data!F47) -> 0 | G47: =HEX2DEC(data!G47) -> 255 | H47: =HEX2DEC(data!H47) -> 15 | I47: =HEX2DEC(data!I47) -> 8 | ... Q47: =HEX2DEC(data!Q47) -> 0 | R47: =MOD(SUM(B47:Q47),256) -> 11
A48: =data!A48 -> C2B0 | B48: =HEX2DEC(data!B48) -> 0 | C48: =HEX2DEC(data!C48) -> 255 | D48: =HEX2DEC(data!D48) -> 15 | E48: =HEX2DEC(data!E48) -> 8 | F48: =HEX2DEC(data!F48) -> 248 | G48: =HEX2DEC(data!G48) -> 255 | H48: =HEX2DEC(data!H48) -> 0 | I48: =HEX2DEC(data!I48) -> 0 | ... Q48: =HEX2DEC(data!Q48) -> 8 | R48: =MOD(SUM(B48:Q48),256) -> 34
...

Sheet data
A1: C000 | B1: FF | C1: FF | D1: FF | E1: FF | F1: FF | G1: FF | H1: FF | I1: FF | J1: FF | K1: FF | L1: FF | M1: FF | N1: FF | O1: FF | P1: FF | Q1: FF
A2: C010 | B2: FF | C2: FF | D2: FF | E2: FF | F2: FF | G2: FF | H2: FF | I2: FF | J2: FF | K2: 80 | L2: 80 | M2: FF | N2: 0 | O2: 0 | P2: FF | Q2: 0
A3: C020 | B3: 0 | C3: FF | D3: 0 | E3: 0 | F3: FF | G3: 80 | H3: 80 | I3: FF | J3: 0 | K3: 0 | L3: FF | M3: 0 | N3: 0 | O3: FF | P3: 0 | Q3: 0
A4: C030 | B4: FF | C4: FF | D4: FF | E4: FF | F4: FC | G4: FC | H4: FF | I4: 0 | J4: 0 | K4: FF | L4: 0 | M4: 0 | N4: 0 | O4: 0 | P4: FF | Q4: 3
A5: C040 | B5: 3 | C5: FF | D5: FF | E5: 0 | F5: 0 | G5: FF | H5: 0 | I5: 0 | J5: 0 | K5: 0 | L5: FF | M5: 1 | N5: 1 | O5: FF | P5: FF | Q5: C0
A6: C050 | B6: C0 | C6: FF | D6: 0 | E6: 0 | F6: 0 | G6: 0 | H6: FF | I6: 0 | J6: 0 | K6: FF | L6: 3F | M6: 30 | N6: F0 | O6: FF | P6: 0 | Q6: 0
A7: C060 | B7: 0 | C7: 0 | D7: FF | E7: 0 | F7: 0 | G7: FF | H7: 1F | I7: 10 | J7: F0 | K7: FF | L7: 0 | M7: 0 | N7: 0 | O7: 0 | P7: FF | Q7: 0
A8: C070 | B8: 0 | C8: FF | D8: 1F | E8: 18 | F8: F8 | G8: FF | H8: 0 | I8: 0 | J8: 0 | K8: 0 | L8: FF | M8: 0 | N8: 0 | O8: FF | P8: 0F | Q8: 8
A9: C080 | B9: F8 | C9: FF | D9: 0 | E9: 0 | F9: 0 | G9: 0 | H9: FF | I9: 0 | J9: 0 | K9: FF | L9: 0F | M9: 8 | N9: F8 | O9: FF | P9: 0 | Q9: 0
A10: C090 | B10: 0 | C10: 0 | D10: FF | E10: 0 | F10: 0 | G10: FF | H10: 0F | I10: 8 | J10: F8 | K10: FF | L10: 0 | M10: 0 | N10: 0 | O10: 0 | P10: FF | Q10: 0
A11: C0A0 | B11: 0 | C11: FF | D11: 0F | E11: 8 | F11: F8 | G11: FF | H11: 0 | I11: 0 | J11: 0 | K11: 0 | L11: FF | M11: 0 | N11: 0 | O11: FF | P11: 0F | Q11: 8
A12: C0B0 | B12: F8 | C12: FF | D12: 0 | E12: 0 | F12: 0 | G12: 0 | H12: FF | I12: 0 | J12: 0 | K12: FF | L12: 0F | M12: 8 | N12: F8 | O12: FF | P12: 0 | Q12: 0
A13: C0C0 | B13: FF | C13: FF | D13: FF | E13: FF | F13: FF | G13: FF | H13: FF | I13: FF | J13: FF | K13: FF | L13: FF | M13: FF | N13: FF | O13: FF | P13: FF | Q13: FF
A14: C0D0 | B14: FF | C14: FF | D14: FF | E14: FF | F14: FF | G14: FF | H14: FF | I14: FF | J14: FF | K14: 0 | L14: 0 | M14: FF | N14: 0 | O14: 0 | P14: FF | Q14: 0
A15: C0E0 | B15: 0 | C15: FF | D15: 1 | E15: 1 | F15: FF | G15: 0 | H15: 0 | I15: FF | J15: 0 | K15: 0 | L15: FF | M15: 0 | N15: 0 | O15: FF | P15: 1 | Q15: 1
A16: C0F0 | B16: FF | C16: 0 | D16: 0 | E16: FF | F16: 0 | G16: 0 | H16: FF | I16: 3F | J16: 3F | K16: FF | L16: FF | M16: FF | N16: FF | O16: 0 | P16: 0 | Q16: FF
A19: C100 | B19: 0 | C19: 0 | D19: FF | E19: C0 | F19: FF | G19: E0 | H19: 0 | I19: FF | J19: FF | K19: 0 | L19: 0 | M19: FF | N19: 3 | O19: 3 | P19: FE | Q19: 80
A20: C110 | B20: FF | C20: 0 | D20: 0 | E20: FF | F20: FF | G20: 0 | H20: 0 | I20: FF | J20: 0C | K20: 0F | L20: F0 | M20: 0 | N20: FF | O20: 0 | P20: 0 | Q20: FF
A21: C120 | B21: FF | C21: 0 | D21: 0 | E21: FF | F21: 8 | G21: 0F | H21: E0 | I21: 0 | J21: FF | K21: 0 | L21: 0 | M21: FF | N21: FF | O21: 0 | P21: 0 | Q21: FF
A22: C130 | B22: 18 | C22: 1F | D22: E0 | E22: 0 | F22: FF | G22: 0 | H22: 0 | I22: FF | J22: FF | K22: 0 | L22: 0 | M22: FF | N22: 10 | O22: 1F | P22: C0 | Q22: 0
A23: C140 | B23: FF | C23: 0 | D23: 0 | E23: FF | F23: FF | G23: 0 | H23: 0 | I23: FF | J23: 10 | K23: 1F | L23: C0 | M23: 0 | N23: FF | O23: 0 | P23: 0 | Q23: FF
A24: C150 | B24: FF | C24: 0 | D24: 0 | E24: FF | F24: 10 | G24: 1F | H24: C0 | I24: 0 | J24: FF | K24: 0 | L24: 0 | M24: FF | N24: FF | O24: 0 | P24: 0 | Q24: FF
A25: C160 | B25: 10 | C25: 1F | D25: C0 | E25: 0 | F25: FF | G25: 0 | H25: 0 | I25: FF | J25: FF | K25: 0 | L25: 0 | M25: FF | N25: 10 | O25: 1F | P25: C0 | Q25: 0
A26: C170 | B26: FF | C26: 0 | D26: 0 | E26: FF | F26: FF | G26: 0 | H26: 0 | I26: FF | J26: 10 | K26: 1F | L26: C0 | M26: 0 | N26: FF | O26: 0 | P26: 0 | Q26: FF
A27: C180 | B27: 80 | C27: 80 | D27: 80 | E27: 0 | F27: 0 | G27: 0 | H27: 0 | I27: 0 | J27: 0 | K27: 0 | L27: 0 | M27: 0 | N27: C0 | O27: C0 | P27: C0 | Q27: 0
A28: C190 | B28: 0 | C28: 0 | D28: 0 | E28: 0 | F28: 0 | G28: 0 | H28: 0 | I28: 0 | J28: E0 | K28: E0 | L28: E0 | M28: 0 | N28: 0 | O28: 0 | P28: 0 | Q28: 0
A29: C1A0 | B29: 0 | C29: 0 | D29: 0 | E29: 0 | F29: 60 | G29: 60 | H29: E0 | I29: 0 | J29: 0 | K29: 0 | L29: 0 | M29: 0 | N29: 0 | O29: 0 | P29: 0 | Q29: 0
A30: C1B0 | B30: 30 | C30: 30 | D30: F0 | E30: 0 | F30: 0 | G30: 0 | H30: 0 | I30: 0 | J30: 0 | K30: 0 | L30: 0 | M30: 0 | N30: 38 | O30: 38 | P30: F8 | Q30: 0
A31: C1C0 | B31: 0 | C31: 0 | D31: 0 | E31: 0 | F31: 0 | G31: 0 | H31: 0 | I31: 0 | J31: 18 | K31: 18 | L31: F8 | M31: 0 | N31: 0 | O31: 0 | P31: 0 | Q31: 0
A32: C1D0 | B32: 0 | C32: 0 | D32: 0 | E32: 0 | F32: 0C | G32: 0C | H32: FC | I32: 0 | J32: 0 | K32: 0 | L32: 0 | M32: 0 | N32: 0 | O32: 0 | P32: 0 | Q32: 0
A33: C1E0 | B33: 0E | C33: 0E | D33: FE | E33: 0 | F33: 0 | G33: 0 | H33: 0 | I33: 0 | J33: 0 | K33: 0 | L33: 0 | M33: 0 | N33: 7 | O33: 7 | P33: FF | Q33: 0
A34: C1F0 | B34: 0 | C34: 0 | D34: 0 | E34: 0 | F34: 0 | G34: 0 | H34: 0 | I34: 0 | J34: 3 | K34: 3 | L34: FF | M34: 0 | N34: 0 | O34: 0 | P34: 0 | Q34: 0
A37: C200 | B37: 0 | C37: 0 | D37: 0 | E37: 0 | F37: 1 | G37: 1 | H37: FF | I37: 80 | J37: 80 | K37: 80 | L37: 0 | M37: 0 | N37: 0 | O37: 0 | P37: 0 | Q37: 0
A38: C210 | B38: 1 | C38: 1 | D38: FF | E38: C0 | F38: C0 | G38: C0 | H38: 0 | I38: 0 | J38: 0 | K38: 0 | L38: 0 | M38: 0 | N38: 0 | O38: 0 | P38: FF | Q38: E0
A39: C220 | B39: E0 | C39: E0 | D39: 0 | E39: 0 | F39: 0 | G39: 0 | H39: 0 | I39: 0 | J39: 0 | K39: 0 | L39: FF | M39: 60 | N39: 60 | O39: E0 | P39: 0 | Q39: 0
A40: C230 | B40: 0 | C40: 0 | D40: 0 | E40: 0 | F40: 0 | G40: 0 | H40: FF | I40: 30 | J40: 30 | K40: F0 | L40: 0 | M40: 0 | N40: 0 | O40: 0 | P40: 0 | Q40: 0
A41: C240 | B41: 0 | C41: 0 | D41: FF | E41: 0 | F41: 0 | G41: FF | H41: 0F | I41: 8 | J41: F8 | K41: FF | L41: 0 | M41: 0 | N41: 0 | O41: 0 | P41: FF | Q41: 0
A42: C250 | B42: 0 | C42: FF | D42: 0F | E42: 8 | F42: F8 | G42: FF | H42: 0 | I42: 0 | J42: 0 | K42: 0 | L42: FF | M42: 0 | N42: 0 | O42: FF | P42: 0F | Q42: 8
A43: C260 | B43: F8 | C43: FF | D43: 0 | E43: 0 | F43: 0 | G43: 0 | H43: FF | I43: 0 | J43: 0 | K43: FF | L43: 0F | M43: 8 | N43: F8 | O43: FF | P43: 0 | Q43: 0
A44: C270 | B44: 0 | C44: 0 | D44: FF | E44: 0 | F44: 0 | G44: FF | H44: 0F | I44: 8 | J44: F8 | K44: FF | L44: 0 | M44: 0 | N44: 0 | O44: 0 | P44: FF | Q44: 0
...
